Traceback (most recent call last):
  File "/Library/Frameworks/Python.framework/Versions/3.12/lib/python3.12/site-packages/jupyter_cache/executors/utils.py", line 58, in single_nb_execution
    executenb(
  File "/Library/Frameworks/Python.framework/Versions/3.12/lib/python3.12/site-packages/nbclient/client.py", line 1314, in execute
    return NotebookClient(nb=nb, resources=resources, km=km, **kwargs).execute()
           ^^^^^^^^^^^^^^^^^^^^^^^^^^^^^^^^^^^^^^^^^^^^^^^^^^^^^^^^^^^^^^^^^^^^^
  File "/Library/Frameworks/Python.framework/Versions/3.12/lib/python3.12/site-packages/jupyter_core/utils/__init__.py", line 165, in wrapped
    return loop.run_until_complete(inner)
           ^^^^^^^^^^^^^^^^^^^^^^^^^^^^^^
  File "/Library/Frameworks/Python.framework/Versions/3.12/lib/python3.12/asyncio/base_events.py", line 687, in run_until_complete
    return future.result()
           ^^^^^^^^^^^^^^^
  File "/Library/Frameworks/Python.framework/Versions/3.12/lib/python3.12/site-packages/nbclient/client.py", line 709, in async_execute
    await self.async_execute_cell(
  File "/Library/Frameworks/Python.framework/Versions/3.12/lib/python3.12/site-packages/nbclient/client.py", line 1062, in async_execute_cell
    await self._check_raise_for_error(cell, cell_index, exec_reply)
  File "/Library/Frameworks/Python.framework/Versions/3.12/lib/python3.12/site-packages/nbclient/client.py", line 918, in _check_raise_for_error
    raise CellExecutionError.from_cell_and_msg(cell, exec_reply_content)
nbclient.exceptions.CellExecutionError: An error occurred while executing the following cell:
------------------
cycle_lst1 = [s+'_cycle' for s in var_lst1]
df.plot(y=cycle_lst, subplots=True, figsize=(8,10))
pass
------------------


[0;31m---------------------------------------------------------------------------[0m
[0;31mNameError[0m                                 Traceback (most recent call last)
Cell [0;32mIn[15], line 2[0m
[1;32m      1[0m cycle_lst1 [38;5;241m=[39m [s[38;5;241m+[39m[38;5;124m'[39m[38;5;124m_cycle[39m[38;5;124m'[39m [38;5;28;01mfor[39;00m s [38;5;129;01min[39;00m var_lst1]
[0;32m----> 2[0m df[38;5;241m.[39mplot(y[38;5;241m=[39m[43mcycle_lst[49m, subplots[38;5;241m=[39m[38;5;28;01mTrue[39;00m, figsize[38;5;241m=[39m([38;5;241m8[39m,[38;5;241m10[39m))
[1;32m      3[0m [38;5;28;01mpass[39;00m

[0;31mNameError[0m: name 'cycle_lst' is not defined

