Traceback (most recent call last):
  File "/Library/Frameworks/Python.framework/Versions/3.12/lib/python3.12/site-packages/jupyter_cache/executors/utils.py", line 58, in single_nb_execution
    executenb(
  File "/Library/Frameworks/Python.framework/Versions/3.12/lib/python3.12/site-packages/nbclient/client.py", line 1314, in execute
    return NotebookClient(nb=nb, resources=resources, km=km, **kwargs).execute()
           ^^^^^^^^^^^^^^^^^^^^^^^^^^^^^^^^^^^^^^^^^^^^^^^^^^^^^^^^^^^^^^^^^^^^^
  File "/Library/Frameworks/Python.framework/Versions/3.12/lib/python3.12/site-packages/jupyter_core/utils/__init__.py", line 165, in wrapped
    return loop.run_until_complete(inner)
           ^^^^^^^^^^^^^^^^^^^^^^^^^^^^^^
  File "/Library/Frameworks/Python.framework/Versions/3.12/lib/python3.12/asyncio/base_events.py", line 687, in run_until_complete
    return future.result()
           ^^^^^^^^^^^^^^^
  File "/Library/Frameworks/Python.framework/Versions/3.12/lib/python3.12/site-packages/nbclient/client.py", line 709, in async_execute
    await self.async_execute_cell(
  File "/Library/Frameworks/Python.framework/Versions/3.12/lib/python3.12/site-packages/nbclient/client.py", line 1062, in async_execute_cell
    await self._check_raise_for_error(cell, cell_index, exec_reply)
  File "/Library/Frameworks/Python.framework/Versions/3.12/lib/python3.12/site-packages/nbclient/client.py", line 918, in _check_raise_for_error
    raise CellExecutionError.from_cell_and_msg(cell, exec_reply_content)
nbclient.exceptions.CellExecutionError: An error occurred while executing the following cell:
------------------
T = 120        # 標本の大きさ
A = 0          # 初期値
A_lst = [A]   # 値を格納するリスト

for i in range(T):
    e = np.random.normal(loc=0,scale=sigma)
    A = rho_tfp * A + e
    A_lst.append(A)

df_A = pd.Series(A_lst)            # Seriesの作成
ax_ = df_A.plot()                   # 図示
ax_.axhline(0, c='red')             # 0の平行線

ac_tfp = df_A.autocorr()       # 自己相関係数の計算
print(f'TFPの自己相関係数：{ac_tfp:.3f}')
------------------


[0;31m---------------------------------------------------------------------------[0m
[0;31mNameError[0m                                 Traceback (most recent call last)
Cell [0;32mIn[43], line 6[0m
[1;32m      3[0m A_lst [38;5;241m=[39m [A]   [38;5;66;03m# 値を格納するリスト[39;00m
[1;32m      5[0m [38;5;28;01mfor[39;00m i [38;5;129;01min[39;00m [38;5;28mrange[39m(T):
[0;32m----> 6[0m     e [38;5;241m=[39m np[38;5;241m.[39mrandom[38;5;241m.[39mnormal(loc[38;5;241m=[39m[38;5;241m0[39m,scale[38;5;241m=[39m[43msigma[49m)
[1;32m      7[0m     A [38;5;241m=[39m rho_tfp [38;5;241m*[39m A [38;5;241m+[39m e
[1;32m      8[0m     A_lst[38;5;241m.[39mappend(A)

[0;31mNameError[0m: name 'sigma' is not defined

