Traceback (most recent call last):
  File "/Library/Frameworks/Python.framework/Versions/3.12/lib/python3.12/site-packages/jupyter_cache/executors/utils.py", line 58, in single_nb_execution
    executenb(
  File "/Library/Frameworks/Python.framework/Versions/3.12/lib/python3.12/site-packages/nbclient/client.py", line 1314, in execute
    return NotebookClient(nb=nb, resources=resources, km=km, **kwargs).execute()
           ^^^^^^^^^^^^^^^^^^^^^^^^^^^^^^^^^^^^^^^^^^^^^^^^^^^^^^^^^^^^^^^^^^^^^
  File "/Library/Frameworks/Python.framework/Versions/3.12/lib/python3.12/site-packages/jupyter_core/utils/__init__.py", line 165, in wrapped
    return loop.run_until_complete(inner)
           ^^^^^^^^^^^^^^^^^^^^^^^^^^^^^^
  File "/Library/Frameworks/Python.framework/Versions/3.12/lib/python3.12/asyncio/base_events.py", line 687, in run_until_complete
    return future.result()
           ^^^^^^^^^^^^^^^
  File "/Library/Frameworks/Python.framework/Versions/3.12/lib/python3.12/site-packages/nbclient/client.py", line 709, in async_execute
    await self.async_execute_cell(
  File "/Library/Frameworks/Python.framework/Versions/3.12/lib/python3.12/site-packages/nbclient/client.py", line 1062, in async_execute_cell
    await self._check_raise_for_error(cell, cell_index, exec_reply)
  File "/Library/Frameworks/Python.framework/Versions/3.12/lib/python3.12/site-packages/nbclient/client.py", line 918, in _check_raise_for_error
    raise CellExecutionError.from_cell_and_msg(cell, exec_reply_content)
nbclient.exceptions.CellExecutionError: An error occurred while executing the following cell:
------------------
df['hours_trend'] = py4macro.trend(df['hours'])
df['hours_cycle'] = 100 * np.log( df['hours']/df['hours_trend'] )

df['employed_trend_log'] = py4macro.trend( np.log(df['employed']) )
df['employed_cycle'] = 100 * ( np.log( df['employed'] ) - df['employed_trend_log'] )

df['total_hours_trend_log'] = py4macro.trend( np.log(df['total_hours']) )
df['total_hours_cycle'] = 100 * ( np.log( df['total_hours'] ) - df['total_hours_trend_log'] )
------------------


[0;31m---------------------------------------------------------------------------[0m
[0;31mNameError[0m                                 Traceback (most recent call last)
Cell [0;32mIn[2], line 1[0m
[0;32m----> 1[0m df[[38;5;124m'[39m[38;5;124mhours_trend[39m[38;5;124m'[39m] [38;5;241m=[39m py4macro[38;5;241m.[39mtrend([43mdf[49m[[38;5;124m'[39m[38;5;124mhours[39m[38;5;124m'[39m])
[1;32m      2[0m df[[38;5;124m'[39m[38;5;124mhours_cycle[39m[38;5;124m'[39m] [38;5;241m=[39m [38;5;241m100[39m [38;5;241m*[39m np[38;5;241m.[39mlog( df[[38;5;124m'[39m[38;5;124mhours[39m[38;5;124m'[39m][38;5;241m/[39mdf[[38;5;124m'[39m[38;5;124mhours_trend[39m[38;5;124m'[39m] )
[1;32m      4[0m df[[38;5;124m'[39m[38;5;124memployed_trend_log[39m[38;5;124m'[39m] [38;5;241m=[39m py4macro[38;5;241m.[39mtrend( np[38;5;241m.[39mlog(df[[38;5;124m'[39m[38;5;124memployed[39m[38;5;124m'[39m]) )

[0;31mNameError[0m: name 'df' is not defined

