Traceback (most recent call last):
  File "/Library/Frameworks/Python.framework/Versions/3.12/lib/python3.12/site-packages/jupyter_cache/executors/utils.py", line 58, in single_nb_execution
    executenb(
  File "/Library/Frameworks/Python.framework/Versions/3.12/lib/python3.12/site-packages/nbclient/client.py", line 1314, in execute
    return NotebookClient(nb=nb, resources=resources, km=km, **kwargs).execute()
           ^^^^^^^^^^^^^^^^^^^^^^^^^^^^^^^^^^^^^^^^^^^^^^^^^^^^^^^^^^^^^^^^^^^^^
  File "/Library/Frameworks/Python.framework/Versions/3.12/lib/python3.12/site-packages/jupyter_core/utils/__init__.py", line 165, in wrapped
    return loop.run_until_complete(inner)
           ^^^^^^^^^^^^^^^^^^^^^^^^^^^^^^
  File "/Library/Frameworks/Python.framework/Versions/3.12/lib/python3.12/asyncio/base_events.py", line 687, in run_until_complete
    return future.result()
           ^^^^^^^^^^^^^^^
  File "/Library/Frameworks/Python.framework/Versions/3.12/lib/python3.12/site-packages/nbclient/client.py", line 709, in async_execute
    await self.async_execute_cell(
  File "/Library/Frameworks/Python.framework/Versions/3.12/lib/python3.12/site-packages/nbclient/client.py", line 1062, in async_execute_cell
    await self._check_raise_for_error(cell, cell_index, exec_reply)
  File "/Library/Frameworks/Python.framework/Versions/3.12/lib/python3.12/site-packages/nbclient/client.py", line 918, in _check_raise_for_error
    raise CellExecutionError.from_cell_and_msg(cell, exec_reply_content)
nbclient.exceptions.CellExecutionError: An error occurred while executing the following cell:
------------------
rbc_basic_model = ls.model(equations = equilibrium_equations,
                           n_states=2,
                           n_exo_states = 1,
                           var_names=var_names,
                           shock_names=shock_names,
                           parameters = parameters)
------------------


[0;31m---------------------------------------------------------------------------[0m
[0;31mTypeError[0m                                 Traceback (most recent call last)
Cell [0;32mIn[6], line 1[0m
[0;32m----> 1[0m rbc_basic_model [38;5;241m=[39m [43mls[49m[38;5;241;43m.[39;49m[43mmodel[49m[43m([49m[43mequations[49m[43m [49m[38;5;241;43m=[39;49m[43m [49m[43mequilibrium_equations[49m[43m,[49m
[1;32m      2[0m [43m                           [49m[43mn_states[49m[38;5;241;43m=[39;49m[38;5;241;43m2[39;49m[43m,[49m
[1;32m      3[0m [43m                           [49m[43mn_exo_states[49m[43m [49m[38;5;241;43m=[39;49m[43m [49m[38;5;241;43m1[39;49m[43m,[49m
[1;32m      4[0m [43m                           [49m[43mvar_names[49m[38;5;241;43m=[39;49m[43mvar_names[49m[43m,[49m
[1;32m      5[0m [43m                           [49m[43mshock_names[49m[38;5;241;43m=[39;49m[43mshock_names[49m[43m,[49m
[1;32m      6[0m [43m                           [49m[43mparameters[49m[43m [49m[38;5;241;43m=[39;49m[43m [49m[43mparameters[49m[43m)[49m

[0;31mTypeError[0m: model.__init__() got an unexpected keyword argument 'var_names'

