Traceback (most recent call last):
  File "/Library/Frameworks/Python.framework/Versions/3.12/lib/python3.12/site-packages/jupyter_cache/executors/utils.py", line 58, in single_nb_execution
    executenb(
  File "/Library/Frameworks/Python.framework/Versions/3.12/lib/python3.12/site-packages/nbclient/client.py", line 1314, in execute
    return NotebookClient(nb=nb, resources=resources, km=km, **kwargs).execute()
           ^^^^^^^^^^^^^^^^^^^^^^^^^^^^^^^^^^^^^^^^^^^^^^^^^^^^^^^^^^^^^^^^^^^^^
  File "/Library/Frameworks/Python.framework/Versions/3.12/lib/python3.12/site-packages/jupyter_core/utils/__init__.py", line 165, in wrapped
    return loop.run_until_complete(inner)
           ^^^^^^^^^^^^^^^^^^^^^^^^^^^^^^
  File "/Library/Frameworks/Python.framework/Versions/3.12/lib/python3.12/asyncio/base_events.py", line 687, in run_until_complete
    return future.result()
           ^^^^^^^^^^^^^^^
  File "/Library/Frameworks/Python.framework/Versions/3.12/lib/python3.12/site-packages/nbclient/client.py", line 709, in async_execute
    await self.async_execute_cell(
  File "/Library/Frameworks/Python.framework/Versions/3.12/lib/python3.12/site-packages/nbclient/client.py", line 1062, in async_execute_cell
    await self._check_raise_for_error(cell, cell_index, exec_reply)
  File "/Library/Frameworks/Python.framework/Versions/3.12/lib/python3.12/site-packages/nbclient/client.py", line 918, in _check_raise_for_error
    raise CellExecutionError.from_cell_and_msg(cell, exec_reply_content)
nbclient.exceptions.CellExecutionError: An error occurred while executing the following cell:
------------------
from myst_nb import glue
cond = bigmac['gdppc_local'].isna()
country_nan = bigmac.loc[cond,'country'].iloc[0]
glue('country_nan_glued',country_nan)
------------------


[0;31m---------------------------------------------------------------------------[0m
[0;31mIndexError[0m                                Traceback (most recent call last)
Cell [0;32mIn[40], line 3[0m
[1;32m      1[0m [38;5;28;01mfrom[39;00m [38;5;21;01mmyst_nb[39;00m [38;5;28;01mimport[39;00m glue
[1;32m      2[0m cond [38;5;241m=[39m bigmac[[38;5;124m'[39m[38;5;124mgdppc_local[39m[38;5;124m'[39m][38;5;241m.[39misna()
[0;32m----> 3[0m country_nan [38;5;241m=[39m [43mbigmac[49m[38;5;241;43m.[39;49m[43mloc[49m[43m[[49m[43mcond[49m[43m,[49m[38;5;124;43m'[39;49m[38;5;124;43mcountry[39;49m[38;5;124;43m'[39;49m[43m][49m[38;5;241;43m.[39;49m[43miloc[49m[43m[[49m[38;5;241;43m0[39;49m[43m][49m
[1;32m      4[0m glue([38;5;124m'[39m[38;5;124mcountry_nan_glued[39m[38;5;124m'[39m,country_nan)

File [0;32m/Library/Frameworks/Python.framework/Versions/3.12/lib/python3.12/site-packages/pandas/core/indexing.py:1191[0m, in [0;36m_LocationIndexer.__getitem__[0;34m(self, key)[0m
[1;32m   1189[0m maybe_callable [38;5;241m=[39m com[38;5;241m.[39mapply_if_callable(key, [38;5;28mself[39m[38;5;241m.[39mobj)
[1;32m   1190[0m maybe_callable [38;5;241m=[39m [38;5;28mself[39m[38;5;241m.[39m_check_deprecated_callable_usage(key, maybe_callable)
[0;32m-> 1191[0m [38;5;28;01mreturn[39;00m [38;5;28;43mself[39;49m[38;5;241;43m.[39;49m[43m_getitem_axis[49m[43m([49m[43mmaybe_callable[49m[43m,[49m[43m [49m[43maxis[49m[38;5;241;43m=[39;49m[43maxis[49m[43m)[49m

File [0;32m/Library/Frameworks/Python.framework/Versions/3.12/lib/python3.12/site-packages/pandas/core/indexing.py:1752[0m, in [0;36m_iLocIndexer._getitem_axis[0;34m(self, key, axis)[0m
[1;32m   1749[0m     [38;5;28;01mraise[39;00m [38;5;167;01mTypeError[39;00m([38;5;124m"[39m[38;5;124mCannot index by location index with a non-integer key[39m[38;5;124m"[39m)
[1;32m   1751[0m [38;5;66;03m# validate the location[39;00m
[0;32m-> 1752[0m [38;5;28;43mself[39;49m[38;5;241;43m.[39;49m[43m_validate_integer[49m[43m([49m[43mkey[49m[43m,[49m[43m [49m[43maxis[49m[43m)[49m
[1;32m   1754[0m [38;5;28;01mreturn[39;00m [38;5;28mself[39m[38;5;241m.[39mobj[38;5;241m.[39m_ixs(key, axis[38;5;241m=[39maxis)

File [0;32m/Library/Frameworks/Python.framework/Versions/3.12/lib/python3.12/site-packages/pandas/core/indexing.py:1685[0m, in [0;36m_iLocIndexer._validate_integer[0;34m(self, key, axis)[0m
[1;32m   1683[0m len_axis [38;5;241m=[39m [38;5;28mlen[39m([38;5;28mself[39m[38;5;241m.[39mobj[38;5;241m.[39m_get_axis(axis))
[1;32m   1684[0m [38;5;28;01mif[39;00m key [38;5;241m>[39m[38;5;241m=[39m len_axis [38;5;129;01mor[39;00m key [38;5;241m<[39m [38;5;241m-[39mlen_axis:
[0;32m-> 1685[0m     [38;5;28;01mraise[39;00m [38;5;167;01mIndexError[39;00m([38;5;124m"[39m[38;5;124msingle positional indexer is out-of-bounds[39m[38;5;124m"[39m)

[0;31mIndexError[0m: single positional indexer is out-of-bounds

